Workbook

Sheet Recipe Costs
A1: # | B1: Recipe | C1: Category | D1: Cost per make (R) | E1: Shop-from-scratch cost (R) | F1: Lines costed | G1: Substitutes / assumed amounts | H1: Not at Woolworths | I1: Basics left out | J1: Post link
A2: 1 | B2: Easy Chicken Pie | C2: Mains | D2: =SUMIFS('Ingredient Costing'!$M$2:$M$559,'Ingredient Costing'!$A$2:$A$559,$B2) -> 281.35513 | E2: =SUMIFS('Ingredient Costing'!$L$2:$L$559,'Ingredient Costing'!$A$2:$A$559,$B2) -> 345.93 | F2: =COUNTIFS('Ingredient Costing'!$A$2:$A$559,$B2,'Ingredient Costing'!$D$2:$D$559,"Costed")+COUNTIFS('Ingredient Costing'!$A$2:$A$559,$B2,'Ingredient Costing'!$D$2:$D$559,"Substitute")+COUNTIFS('Ingredient Costing'!$A$2:$A$559,$B2,'Ingredient Costing'!$D$2:$D$559,"Uses 5 Veg Mince") -> 7 | G2: =SUMPRODUCT(('Ingredient Costing'!$A$2:$A$559=$B2)*(('Ingredient Costing'!$D$2:$D$559="Substitute")+(LEFT('Ingredient Costing'!$N$2:$N$559,16)="Amount not given")>0)) -> 2 | H2: =COUNTIFS('Ingredient Costing'!$A$2:$A$559,$B2,'Ingredient Costing'!$D$2:$D$559,"Not at Woolworths") -> 0 | I2: =COUNTIFS('Ingredient Costing'!$A$2:$A$559,$B2,'Ingredient Costing'!$D$2:$D$559,"Basic - not costed") -> 0 | J2: Open post
A3: 2 | B3: Bougie-Up Your Veg (toppings) | C3: Sides & salads | D3: =SUMIFS('Ingredient Costing'!$M$2:$M$559,'Ingredient Costing'!$A$2:$A$559,$B3) -> 100.41483 | E3: =SUMIFS('Ingredient Costing'!$L$2:$L$559,'Ingredient Costing'!$A$2:$A$559,$B3) -> 339.93 | F3: =COUNTIFS('Ingredient Costing'!$A$2:$A$559,$B3,'Ingredient Costing'!$D$2:$D$559,"Costed")+COUNTIFS('Ingredient Costing'!$A$2:$A$559,$B3,'Ingredient Costing'!$D$2:$D$559,"Substitute")+COUNTIFS('Ingredient Costing'!$A$2:$A$559,$B3,'Ingredient Costing'!$D$2:$D$559,"Uses 5 Veg Mince") -> 7 | G3: =SUMPRODUCT(('Ingredient Costing'!$A$2:$A$559=$B3)*(('Ingredient Costing'!$D$2:$D$559="Substitute")+(LEFT('Ingredient Costing'!$N$2:$N$559,16)="Amount not given")>0)) -> 6 | H3: =COUNTIFS('Ingredient Costing'!$A$2:$A$559,$B3,'Ingredient Costing'!$D$2:$D$559,"Not at Woolworths") -> 0 | I3: =COUNTIFS('Ingredient Costing'!$A$2:$A$559,$B3,'Ingredient Costing'!$D$2:$D$559,"Basic - not costed") -> 0 | J3: Open post
A4: 3 | B4: Spinach & Feta Filo Tart | C4: Mains | D4: =SUMIFS('Ingredient Costing'!$M$2:$M$559,'Ingredient Costing'!$A$2:$A$559,$B4) -> 101.48204 | E4: =SUMIFS('Ingredient Costing'!$L$2:$L$559,'Ingredient Costing'!$A$2:$A$559,$B4) -> 501.82 | F4: =COUNTIFS('Ingredient Costing'!$A$2:$A$559,$B4,'Ingredient Costing'!$D$2:$D$559,"Costed")+COUNTIFS('Ingredient Costing'!$A$2:$A$559,$B4,'Ingredient Costing'!$D$2:$D$559,"Substitute")+COUNTIFS('Ingredient Costing'!$A$2:$A$559,$B4,'Ingredient Costing'!$D$2:$D$559,"Uses 5 Veg Mince") -> 8 | G4: =SUMPRODUCT(('Ingredient Costing'!$A$2:$A$559=$B4)*(('Ingredient Costing'!$D$2:$D$559="Substitute")+(LEFT('Ingredient Costing'!$N$2:$N$559,16)="Amount not given")>0)) -> 2 | H4: =COUNTIFS('Ingredient Costing'!$A$2:$A$559,$B4,'Ingredient Costing'!$D$2:$D$559,"Not at Woolworths") -> 0 | I4: =COUNTIFS('Ingredient Costing'!$A$2:$A$559,$B4,'Ingredient Costing'!$D$2:$D$559,"Basic - not costed") -> 1 | J4: Open post
A5: 4 | B5: Pampoen Tert (lower-sugar) | C5: Baking & sweet treats | D5: =SUMIFS('Ingredient Costing'!$M$2:$M$559,'Ingredient Costing'!$A$2:$A$559,$B5) -> 102.58268 | E5: =SUMIFS('Ingredient Costing'!$L$2:$L$559,'Ingredient Costing'!$A$2:$A$559,$B5) -> 299.92 | F5: =COUNTIFS('Ingredient Costing'!$A$2:$A$559,$B5,'Ingredient Costing'!$D$2:$D$559,"Costed")+COUNTIFS('Ingredient Costing'!$A$2:$A$559,$B5,'Ingredient Costing'!$D$2:$D$559,"Substitute")+COUNTIFS('Ingredient Costing'!$A$2:$A$559,$B5,'Ingredient Costing'!$D$2:$D$559,"Uses 5 Veg Mince") -> 9 | G5: =SUMPRODUCT(('Ingredient Costing'!$A$2:$A$559=$B5)*(('Ingredient Costing'!$D$2:$D$559="Substitute")+(LEFT('Ingredient Costing'!$N$2:$N$559,16)="Amount not given")>0)) -> 1 | H5: =COUNTIFS('Ingredient Costing'!$A$2:$A$559,$B5,'Ingredient Costing'!$D$2:$D$559,"Not at Woolworths") -> 0 | I5: =COUNTIFS('Ingredient Costing'!$A$2:$A$559,$B5,'Ingredient Costing'!$D$2:$D$559,"Basic - not costed") -> 1 | J5: Open post
A6: 5 | B6: Sticky Glazed Meatloaf | C6: Mains | D6: =SUMIFS('Ingredient Costing'!$M$2:$M$559,'Ingredient Costing'!$A$2:$A$559,$B6) -> 233.84319 | E6: =SUMIFS('Ingredient Costing'!$L$2:$L$559,'Ingredient Costing'!$A$2:$A$559,$B6) -> 481.79 | F6: =COUNTIFS('Ingredient Costing'!$A$2:$A$559,$B6,'Ingredient Costing'!$D$2:$D$559,"Costed")+COUNTIFS('Ingredient Costing'!$A$2:$A$559,$B6,'Ingredient Costing'!$D$2:$D$559,"Substitute")+COUNTIFS('Ingredient Costing'!$A$2:$A$559,$B6,'Ingredient Costing'!$D$2:$D$559,"Uses 5 Veg Mince") -> 13 | G6: =SUMPRODUCT(('Ingredient Costing'!$A$2:$A$559=$B6)*(('Ingredient Costing'!$D$2:$D$559="Substitute")+(LEFT('Ingredient Costing'!$N$2:$N$559,16)="Amount not given")>0)) -> 1 | H6: =COUNTIFS('Ingredient Costing'!$A$2:$A$559,$B6,'Ingredient Costing'!$D$2:$D$559,"Not at Woolworths") -> 0 | I6: =COUNTIFS('Ingredient Costing'!$A$2:$A$559,$B6,'Ingredient Costing'!$D$2:$D$559,"Basic - not costed") -> 2 | J6: Open post
A7: 6 | B7: Fancy Fish Paste | C7: Snacks | D7: =SUMIFS('Ingredient Costing'!$M$2:$M$559,'Ingredient Costing'!$A$2:$A$559,$B7) -> 57.216 | E7: =SUMIFS('Ingredient Costing'!$L$2:$L$559,'Ingredient Costing'!$A$2:$A$559,$B7) -> 261.94 | F7: =COUNTIFS('Ingredient Costing'!$A$2:$A$559,$B7,'Ingredient Costing'!$D$2:$D$559,"Costed")+COUNTIFS('Ingredient Costing'!$A$2:$A$559,$B7,'Ingredient Costing'!$D$2:$D$559,"Substitute")+COUNTIFS('Ingredient Costing'!$A$2:$A$559,$B7,'Ingredient Costing'!$D$2:$D$559,"Uses 5 Veg Mince") -> 6 | G7: =SUMPRODUCT(('Ingredient Costing'!$A$2:$A$559=$B7)*(('Ingredient Costing'!$D$2:$D$559="Substitute")+(LEFT('Ingredient Costing'!$N$2:$N$559,16)="Amount not given")>0)) -> 4 | H7: =COUNTIFS('Ingredient Costing'!$A$2:$A$559,$B7,'Ingredient Costing'!$D$2:$D$559,"Not at Woolworths") -> 0 | I7: =COUNTIFS('Ingredient Costing'!$A$2:$A$559,$B7,'Ingredient Costing'!$D$2:$D$559,"Basic - not costed") -> 1 | J7: Open post
A8: 7 | B8: Easy Yoghurt Dressing | C8: Sauces & dressings | D8: =SUMIFS('Ingredient Costing'!$M$2:$M$559,'Ingredient Costing'!$A$2:$A$559,$B8) -> 34.3203 | E8: =SUMIFS('Ingredient Costing'!$L$2:$L$559,'Ingredient Costing'!$A$2:$A$559,$B8) -> 163.95 | F8: =COUNTIFS('Ingredient Costing'!$A$2:$A$559,$B8,'Ingredient Costing'!$D$2:$D$559,"Costed")+COUNTIFS('Ingredient Costing'!$A$2:$A$559,$B8,'Ingredient Costing'!$D$2:$D$559,"Substitute")+COUNTIFS('Ingredient Costing'!$A$2:$A$559,$B8,'Ingredient Costing'!$D$2:$D$559,"Uses 5 Veg Mince") -> 5 | G8: =SUMPRODUCT(('Ingredient Costing'!$A$2:$A$559=$B8)*(('Ingredient Costing'!$D$2:$D$559="Substitute")+(LEFT('Ingredient Costing'!$N$2:$N$559,16)="Amount not given")>0)) -> 1 | H8: =COUNTIFS('Ingredient Costing'!$A$2:$A$559,$B8,'Ingredient Costing'!$D$2:$D$559,"Not at Woolworths") -> 0 | I8: =COUNTIFS('Ingredient Costing'!$A$2:$A$559,$B8,'Ingredient Costing'!$D$2:$D$559,"Basic - not costed") -> 1 | J8: Open post
A9: 8 | B9: Hoisin Pork Fillet (with noodles) | C9: Mains | D9: =SUMIFS('Ingredient Costing'!$M$2:$M$559,'Ingredient Costing'!$A$2:$A$559,$B9) -> 299.98727 | E9: =SUMIFS('Ingredient Costing'!$L$2:$L$559,'Ingredient Costing'!$A$2:$A$559,$B9) -> 796.88 | F9: =COUNTIFS('Ingredient Costing'!$A$2:$A$559,$B9,'Ingredient Costing'!$D$2:$D$559,"Costed")+COUNTIFS('Ingredient Costing'!$A$2:$A$559,$B9,'Ingredient Costing'!$D$2:$D$559,"Substitute")+COUNTIFS('Ingredient Costing'!$A$2:$A$559,$B9,'Ingredient Costing'!$D$2:$D$559,"Uses 5 Veg Mince") -> 14 | G9: =SUMPRODUCT(('Ingredient Costing'!$A$2:$A$559=$B9)*(('Ingredient Costing'!$D$2:$D$559="Substitute")+(LEFT('Ingredient Costing'!$N$2:$N$559,16)="Amount not given")>0)) -> 1 | H9: =COUNTIFS('Ingredient Costing'!$A$2:$A$559,$B9,'Ingredient Costing'!$D$2:$D$559,"Not at Woolworths") -> 0 | I9: =COUNTIFS('Ingredient Costing'!$A$2:$A$559,$B9,'Ingredient Costing'!$D$2:$D$559,"Basic - not costed") -> 0 | J9: Open post
A10: 9 | B10: Crispy Chickpeas | C10: Snacks | D10: =SUMIFS('Ingredient Costing'!$M$2:$M$559,'Ingredient Costing'!$A$2:$A$559,$B10) -> 49.6499 | E10: =SUMIFS('Ingredient Costing'!$L$2:$L$559,'Ingredient Costing'!$A$2:$A$559,$B10) -> 202.95 | F10: =COUNTIFS('Ingredient Costing'!$A$2:$A$559,$B10,'Ingredient Costing'!$D$2:$D$559,"Costed")+COUNTIFS('Ingredient Costing'!$A$2:$A$559,$B10,'Ingredient Costing'!$D$2:$D$559,"Substitute")+COUNTIFS('Ingredient Costing'!$A$2:$A$559,$B10,'Ingredient Costing'!$D$2:$D$559,"Uses 5 Veg Mince") -> 5 | G10: =SUMPRODUCT(('Ingredient Costing'!$A$2:$A$559=$B10)*(('Ingredient Costing'!$D$2:$D$559="Substitute")+(LEFT('Ingredient Costing'!$N$2:$N$559,16)="Amount not given")>0)) -> 4 | H10: =COUNTIFS('Ingredient Costing'!$A$2:$A$559,$B10,'Ingredient Costing'!$D$2:$D$559,"Not at Woolworths") -> 0 | I10: =COUNTIFS('Ingredient Costing'!$A$2:$A$559,$B10,'Ingredient Costing'!$D$2:$D$559,"Basic - not costed") -> 1 | J10: Open post
A11: 10 | B11: Homemade Hot Choccie | C11: Drinks | D11: =SUMIFS('Ingredient Costing'!$M$2:$M$559,'Ingredient Costing'!$A$2:$A$559,$B11) -> 9.84966 | E11: =SUMIFS('Ingredient Costing'!$L$2:$L$559,'Ingredient Costing'!$A$2:$A$559,$B11) -> 141.97 | F11: =COUNTIFS('Ingredient Costing'!$A$2:$A$559,$B11,'Ingredient Costing'!$D$2:$D$559,"Costed")+COUNTIFS('Ingredient Costing'!$A$2:$A$559,$B11,'Ingredient Costing'!$D$2:$D$559,"Substitute")+COUNTIFS('Ingredient Costing'!$A$2:$A$559,$B11,'Ingredient Costing'!$D$2:$D$559,"Uses 5 Veg Mince") -> 3 | G11: =SUMPRODUCT(('Ingredient Costing'!$A$2:$A$559=$B11)*(('Ingredient Costing'!$D$2:$D$559="Substitute")+(LEFT('Ingredient Costing'!$N$2:$N$559,16)="Amount not given")>0)) -> 0 | H11: =COUNTIFS('Ingredient Costing'!$A$2:$A$559,$B11,'Ingredient Costing'!$D$2:$D$559,"Not at Woolworths") -> 0 | I11: =COUNTIFS('Ingredient Costing'!$A$2:$A$559,$B11,'Ingredient Costing'!$D$2:$D$559,"Basic - not costed") -> 0 | J11: Open post
A12: 11 | B12: Cottage Pie with Crispy Potato & Parmesan Crust | C12: Mains | D12: =SUMIFS('Ingredient Costing'!$M$2:$M$559,'Ingredient Costing'!$A$2:$A$559,$B12) -> 258.52809 | E12: =SUMIFS('Ingredient Costing'!$L$2:$L$559,'Ingredient Costing'!$A$2:$A$559,$B12) -> 499.76 | F12: =COUNTIFS('Ingredient Costing'!$A$2:$A$559,$B12,'Ingredient Costing'!$D$2:$D$559,"Costed")+COUNTIFS('Ingredient Costing'!$A$2:$A$559,$B12,'Ingredient Costing'!$D$2:$D$559,"Substitute")+COUNTIFS('Ingredient Costing'!$A$2:$A$559,$B12,'Ingredient Costing'!$D$2:$D$559,"Uses 5 Veg Mince") -> 14 | G12: =SUMPRODUCT(('Ingredient Costing'!$A$2:$A$559=$B12)*(('Ingredient Costing'!$D$2:$D$559="Substitute")+(LEFT('Ingredient Costing'!$N$2:$N$559,16)="Amount not given")>0)) -> 4 | H12: =COUNTIFS('Ingredient Costing'!$A$2:$A$559,$B12,'Ingredient Costing'!$D$2:$D$559,"Not at Woolworths") -> 0 | I12: =COUNTIFS('Ingredient Costing'!$A$2:$A$559,$B12,'Ingredient Costing'!$D$2:$D$559,"Basic - not costed") -> 1 | J12: Open post
A13: 12 | B13: Quick & Easy Chicken Parmigiana | C13: Mains | D13: =SUMIFS('Ingredient Costing'!$M$2:$M$559,'Ingredient Costing'!$A$2:$A$559,$B13) -> 248.5015 | E13: =SUMIFS('Ingredient Costing'!$L$2:$L$559,'Ingredient Costing'!$A$2:$A$559,$B13) -> 387.94 | F13: =COUNTIFS('Ingredient Costing'!$A$2:$A$559,$B13,'Ingredient Costing'!$D$2:$D$559,"Costed")+COUNTIFS('Ingredient Costing'!$A$2:$A$559,$B13,'Ingredient Costing'!$D$2:$D$559,"Substitute")+COUNTIFS('Ingredient Costing'!$A$2:$A$559,$B13,'Ingredient Costing'!$D$2:$D$559,"Uses 5 Veg Mince") -> 7 | G13: =SUMPRODUCT(('Ingredient Costing'!$A$2:$A$559=$B13)*(('Ingredient Costing'!$D$2:$D$559="Substitute")+(LEFT('Ingredient Costing'!$N$2:$N$559,16)="Amount not given")>0)) -> 6 | H13: =COUNTIFS('Ingredient Costing'!$A$2:$A$559,$B13,'Ingredient Costing'!$D$2:$D$559,"Not at Woolworths") -> 0 | I13: =COUNTIFS('Ingredient Costing'!$A$2:$A$559,$B13,'Ingredient Costing'!$D$2:$D$559,"Basic - not costed") -> 1 | J13: Open post
... A68: 67 | B68: Biscoff Crumble Vanilla Ice Cream | C68: Desserts & ice cream | D68: =SUMIFS('Ingredient Costing'!$M$2:$M$559,'Ingredient Costing'!$A$2:$A$559,$B68) -> 108.1245 | E68: =SUMIFS('Ingredient Costing'!$L$2:$L$559,'Ingredient Costing'!$A$2:$A$559,$B68) -> 179.95 | F68: =COUNTIFS('Ingredient Costing'!$A$2:$A$559,$B68,'Ingredient Costing'!$D$2:$D$559,"Costed")+COUNTIFS('Ingredient Costing'!$A$2:$A$559,$B68,'Ingredient Costing'!$D$2:$D$559,"Substitute")+COUNTIFS('Ingredient Costing'!$A$2:$A$559,$B68,'Ingredient Costing'!$D$2:$D$559,"Uses 5 Veg Mince") -> 5 | G68: =SUMPRODUCT(('Ingredient Costing'!$A$2:$A$559=$B68)*(('Ingredient Costing'!$D$2:$D$559="Substitute")+(LEFT('Ingredient Costing'!$N$2:$N$559,16)="Amount not given")>0)) -> 1 | H68: =COUNTIFS('Ingredient Costing'!$A$2:$A$559,$B68,'Ingredient Costing'!$D$2:$D$559,"Not at Woolworths") -> 0 | I68: =COUNTIFS('Ingredient Costing'!$A$2:$A$559,$B68,'Ingredient Costing'!$D$2:$D$559,"Basic - not costed") -> 1 | J68: Open post
B70: Average per recipe | D70: =AVERAGE(D2:D68) -> 174.20285 | E70: =AVERAGE(E2:E68) -> 378.05567
B71: =" Prices: woolworths.co.za, 6 Oct 2026 - basis: "&'Notes & Assumptions'!$C$4 -> Prices: woolworths.co.za, 6 Oct 2026 - basis: Today
B72: See the Notes & Assumptions tab for what is and isn't included.

Sheet Recipes
A1: # | B1: Recipe | C1: Category | D1: Ingredients | E1: No. of ingredients | F1: Notes | G1: Post link | H1: Cost per make (R) | I1: Shop-from-scratch cost (R)
A2: 1 | B2: Easy Chicken Pie | C2: Mains | D2: • 1 packet fresh chicken soup • 1 cup lightly cooked vegetables (diced baby marrows & carrots) • 1 rotisserie chicken (breast & thigh), sliced • Puff pastry • 1 egg, for brushing • Green salad, to serve | E2: 6 | F2: Bake 180°C ~40 min. Pinned post. | G2: https://www.instagram.com/jadeseeliger_dietitian/reel/C4Pw3ETK0PZ/ | H2: =INDEX('Recipe Costs'!$D$2:$D$68,MATCH($B2,'Recipe Costs'!$B$2:$B$68,0)) -> 281.35513 | I2: =INDEX('Recipe Costs'!$E$2:$E$68,MATCH($B2,'Recipe Costs'!$B$2:$B$68,0)) -> 345.93
A3: 2 | B3: Bougie-Up Your Veg (toppings) | C3: Sides & salads | D3: • Cooked vegetables of choice • Feta, crumbled • Pomegranate seeds • Lemon zest • Balsamic glaze • Rocket leaves • Good olive oil | E3: 7 | F3: A topping idea rather than a full recipe. | G3: https://www.instagram.com/jadeseeliger_dietitian/reel/DeE9erkuKNG/ | H3: =INDEX('Recipe Costs'!$D$2:$D$68,MATCH($B3,'Recipe Costs'!$B$2:$B$68,0)) -> 100.41483 | I3: =INDEX('Recipe Costs'!$E$2:$E$68,MATCH($B3,'Recipe Costs'!$B$2:$B$68,0)) -> 339.93
A4: 3 | B4: Spinach & Feta Filo Tart | C4: Mains | D4: • 2–3 sheets filo pastry (+1 extra for topping) • Olive oil spray • 500 g spinach • 2 eggs • 1 round feta, crumbled • 1 onion, diced • Zest of 1 lemon • Sesame seeds • Salt | E4: 9 | F4: Bake 180°C ~30 min. | G4: https://www.instagram.com/jadeseeliger_dietitian/reel/Dd8O2VGO5wJ/ | H4: =INDEX('Recipe Costs'!$D$2:$D$68,MATCH($B4,'Recipe Costs'!$B$2:$B$68,0)) -> 101.48204 | I4: =INDEX('Recipe Costs'!$E$2:$E$68,MATCH($B4,'Recipe Costs'!$B$2:$B$68,0)) -> 501.82
A5: 4 | B5: Pampoen Tert (lower-sugar) | C5: Baking & sweet treats | D5: • 800 g pumpkin, cooked & mashed • 2 cups flour • 3 eggs • ¼ cup sugar • 3 tsp baking powder • 1 tsp salt • 1 Tbsp vanilla essence • 50 g butter, melted • Cinnamon & sugar, to sprinkle | E5: 9 | F5: Bake 180°C 30–35 min. | G5: https://www.instagram.com/jadeseeliger_dietitian/reel/Ddy_YDmuIFf/ | H5: =INDEX('Recipe Costs'!$D$2:$D$68,MATCH($B5,'Recipe Costs'!$B$2:$B$68,0)) -> 102.58268 | I5: =INDEX('Recipe Costs'!$E$2:$E$68,MATCH($B5,'Recipe Costs'!$B$2:$B$68,0)) -> 299.92
A6: 5 | B6: Sticky Glazed Meatloaf | C6: Mains | D6: • 1 kg lean beef mince • 1 medium onion, finely chopped • 2 green apples, grated • 2 large eggs • 3 garlic cloves, minced • 2 Tbsp tomato sauce • 3 Tbsp fresh parsley (or 1 Tbsp dried Italian herbs) • ¾ cup breadcrumbs • ⅔ cup milk • 1 tsp salt • 1 tsp Italian seasoning • ½ tsp ground black pepper • Glaze: ⅓ cup tomato sauce • Glaze: ⅓ cup HP sauce • Glaze: 2 Tbsp vinegar | E6: 15 | F6: 180°C 40 min, glaze, then 15 min more. Served with mash & petit pois. | G6: https://www.instagram.com/jadeseeliger_dietitian/reel/DdndJTwOoVo/ | H6: =INDEX('Recipe Costs'!$D$2:$D$68,MATCH($B6,'Recipe Costs'!$B$2:$B$68,0)) -> 233.84319 | I6: =INDEX('Recipe Costs'!$E$2:$E$68,MATCH($B6,'Recipe Costs'!$B$2:$B$68,0)) -> 481.79
A7: 6 | B7: Fancy Fish Paste | C7: Snacks | D7: • 1 tin sardines, drained • ½ red onion, chopped • Lemon juice • Fresh coriander • Toast, to serve • Black pepper • Chilli oil (optional) | E7: 7 | F7: Blend and spread on toast. | G7: https://www.instagram.com/jadeseeliger_dietitian/reel/DdVYOW3OQ-B/ | H7: =INDEX('Recipe Costs'!$D$2:$D$68,MATCH($B7,'Recipe Costs'!$B$2:$B$68,0)) -> 57.216 | I7: =INDEX('Recipe Costs'!$E$2:$E$68,MATCH($B7,'Recipe Costs'!$B$2:$B$68,0)) -> 261.94
A8: 7 | B8: Easy Yoghurt Dressing | C8: Sauces & dressings | D8: • ½ cup yoghurt • Juice + zest of 1 lemon • 1 Tbsp mayonnaise • Salt & pepper • Fresh chives, chopped • 2 garlic cloves, crushed | E8: 6 | F8: Keeps 3–4 days in the fridge. | G8: https://www.instagram.com/jadeseeliger_dietitian/reel/DdRkcBTuh1n/ | H8: =INDEX('Recipe Costs'!$D$2:$D$68,MATCH($B8,'Recipe Costs'!$B$2:$B$68,0)) -> 34.3203 | I8: =INDEX('Recipe Costs'!$E$2:$E$68,MATCH($B8,'Recipe Costs'!$B$2:$B$68,0)) -> 163.95
A9: 8 | B9: Hoisin Pork Fillet (with noodles) | C9: Mains | D9: • 4 Tbsp hoisin sauce (+ extra to serve) • 1 pork fillet, trimmed • 3 whole-wheat egg noodle nests • 1 Tbsp sesame oil • 1 Tbsp grated ginger • 2 garlic cloves, crushed • 200 g baby spinach • 1 bunch spring onions, sliced • 110 g podded edamame beans • 1 Tbsp sesame seeds, toasted (+1 tsp to garnish) • 1 avocado, cubed • Lemon juice (for the avo) • 2 tsp low-salt soy sauce • 1 Tbsp rice vinegar | E9: 14 | F9: Serves 4. Air fryer 180°C 7 min or oven 15 min. | G9: https://www.instagram.com/jadeseeliger_dietitian/reel/DdO8M8FuXEr/ | H9: =INDEX('Recipe Costs'!$D$2:$D$68,MATCH($B9,'Recipe Costs'!$B$2:$B$68,0)) -> 299.98727 | I9: =INDEX('Recipe Costs'!$E$2:$E$68,MATCH($B9,'Recipe Costs'!$B$2:$B$68,0)) -> 796.88
A10: 9 | B10: Crispy Chickpeas | C10: Snacks | D10: • 1 tin chickpeas • Lemon-flavoured olive oil • Lemon (juice) • Fresh rosemary • Garlic • Salt | E10: 6 | F10: Air fryer 180°C ~40 min. | G10: https://www.instagram.com/jadeseeliger_dietitian/reel/DdHG5X4uiMl/ | H10: =INDEX('Recipe Costs'!$D$2:$D$68,MATCH($B10,'Recipe Costs'!$B$2:$B$68,0)) -> 49.6499 | I10: =INDEX('Recipe Costs'!$E$2:$E$68,MATCH($B10,'Recipe Costs'!$B$2:$B$68,0)) -> 202.95
A11: 10 | B11: Homemade Hot Choccie | C11: Drinks | D11: • 1 cup full-cream or low-fat milk • 1 Tbsp cocoa powder • 1 tsp sugar | E11: 3 | F11: Serves 1 – multiply for the family. | G11: https://www.instagram.com/jadeseeliger_dietitian/reel/DdCENQ7u7V6/ | H11: =INDEX('Recipe Costs'!$D$2:$D$68,MATCH($B11,'Recipe Costs'!$B$2:$B$68,0)) -> 9.84966 | I11: =INDEX('Recipe Costs'!$E$2:$E$68,MATCH($B11,'Recipe Costs'!$B$2:$B$68,0)) -> 141.97
A12: 11 | B12: Cottage Pie with Crispy Potato & Parmesan Crust | C12: Mains | D12: • 500 g lean mince • 1 medium onion, chopped • 2–3 garlic cloves, crushed • 2 medium carrots, grated • 2 large mushrooms, grated • 4–5 baby marrows, grated • 2 tomatoes, diced • 1 tin tomato & onion mix • 2 sachets tomato paste • Fresh basil/thyme • 1 tsp sugar • ½ tsp salt • Pre-cooked potatoes, sliced • Parmesan, grated • Fresh thyme | E12: 15 | F12: Mince simmers 30–40 min; air fryer 200°C ~20 min to finish. | G12: https://www.instagram.com/jadeseeliger_dietitian/reel/DdCER0yh3Ue/ | H12: =INDEX('Recipe Costs'!$D$2:$D$68,MATCH($B12,'Recipe Costs'!$B$2:$B$68,0)) -> 258.52809 | I12: =INDEX('Recipe Costs'!$E$2:$E$68,MATCH($B12,'Recipe Costs'!$B$2:$B$68,0)) -> 499.76
A13: 12 | B13: Quick & Easy Chicken Parmigiana | C13: Mains | D13: • Deboned skinless chicken thighs • Plain yoghurt (marinade) • Breadcrumbs • Salt & pepper • Italian herbs • Zest of 1 lemon • Ready-made tomato soup • Grated cheddar | E13: 8 | F13: No quantities given. | G13: https://www.instagram.com/jadeseeliger_dietitian/reel/Dcq5Ap0h3tG/ | H13: =INDEX('Recipe Costs'!$D$2:$D$68,MATCH($B13,'Recipe Costs'!$B$2:$B$68,0)) -> 248.5015 | I13: =INDEX('Recipe Costs'!$E$2:$E$68,MATCH($B13,'Recipe Costs'!$B$2:$B$68,0)) -> 387.94
... A68: 67 | B68: Biscoff Crumble Vanilla Ice Cream | C68: Desserts & ice cream | D68: • 500 ml fresh cream • ½ cup white sugar • 1 cup milk • 2 tsp vanilla extract • 1 tsp salt • Biscoff biscuits, crushed | E68: 6 | F68: Churned in an ice-cream maker (~30 min). | G68: https://www.instagram.com/jadeseeliger_dietitian/reel/DU7hE3UiBVI/ | H68: =INDEX('Recipe Costs'!$D$2:$D$68,MATCH($B68,'Recipe Costs'!$B$2:$B$68,0)) -> 108.1245 | I68: =INDEX('Recipe Costs'!$E$2:$E$68,MATCH($B68,'Recipe Costs'!$B$2:$B$68,0)) -> 179.95

Sheet Ingredient Costing
A1: Recipe | B1: Category | C1: Ingredient (from post) | D1: Status | E1: Product key | F1: Woolworths product | G1: Qty used | H1: Unit | I1: Pack size | J1: Pack price (R) | K1: Packs to buy | L1: Shop cost (R) | M1: Cost of amount used (R) | N1: Note / assumption
A2: Easy Chicken Pie | B2: Mains | C2: 1 packet fresh chicken soup | D2: Costed | E2: fresh_chicken_soup | F2: =INDEX('Woolworths Products'!$B$2:$B$208,MATCH($E2,'Woolworths Products'!$A$2:$A$208,0)) -> Farmhouse Chicken Soup 600 g | G2: 1 | H2: =INDEX('Woolworths Products'!$G$2:$G$208,MATCH($E2,'Woolworths Products'!$A$2:$A$208,0)) -> ea | I2: =INDEX('Woolworths Products'!$F$2:$F$208,MATCH($E2,'Woolworths Products'!$A$2:$A$208,0)) -> 1 | J2: =INDEX('Woolworths Products'!$E$2:$E$208,MATCH($E2,'Woolworths Products'!$A$2:$A$208,0)) -> 74.99 | K2: =IF(COUNTIFS($A$2:A2,A2,$E$2:E2,E2)=1,ROUNDUP(SUMIFS($G:$G,$A:$A,A2,$E:$E,E2)/I2,0),0) -> 1 | L2: =K2*J2 -> 74.99 | M2: =G2/I2*J2 -> 74.99
A3: Easy Chicken Pie | B3: Mains | C3: 1 cup lightly cooked vegetables (diced baby marrows & carrots) | D3: Costed | E3: baby_marrows | F3: =INDEX('Woolworths Products'!$B$2:$B$208,MATCH($E3,'Woolworths Products'!$A$2:$A$208,0)) -> Baby Marrows 350 g | G3: 70 | H3: =INDEX('Woolworths Products'!$G$2:$G$208,MATCH($E3,'Woolworths Products'!$A$2:$A$208,0)) -> g | I3: =INDEX('Woolworths Products'!$F$2:$F$208,MATCH($E3,'Woolworths Products'!$A$2:$A$208,0)) -> 350 | J3: =INDEX('Woolworths Products'!$E$2:$E$208,MATCH($E3,'Woolworths Products'!$A$2:$A$208,0)) -> 32.99 | K3: =IF(COUNTIFS($A$2:A3,A3,$E$2:E3,E3)=1,ROUNDUP(SUMIFS($G:$G,$A:$A,A3,$E:$E,E3)/I3,0),0) -> 1 | L3: =K3*J3 -> 32.99 | M3: =G3/I3*J3 -> 6.598 | N3: 1 cup veg split as ~70 g baby marrow + ~60 g carrot
A4: Easy Chicken Pie | B4: Mains | C4: 1 cup lightly cooked vegetables (diced baby marrows & carrots) (part 2) | D4: Costed | E4: carrots | F4: =INDEX('Woolworths Products'!$B$2:$B$208,MATCH($E4,'Woolworths Products'!$A$2:$A$208,0)) -> Medium Carrots 500 g | G4: 60 | H4: =INDEX('Woolworths Products'!$G$2:$G$208,MATCH($E4,'Woolworths Products'!$A$2:$A$208,0)) -> g | I4: =INDEX('Woolworths Products'!$F$2:$F$208,MATCH($E4,'Woolworths Products'!$A$2:$A$208,0)) -> 500 | J4: =INDEX('Woolworths Products'!$E$2:$E$208,MATCH($E4,'Woolworths Products'!$A$2:$A$208,0)) -> 14.99 | K4: =IF(COUNTIFS($A$2:A4,A4,$E$2:E4,E4)=1,ROUNDUP(SUMIFS($G:$G,$A:$A,A4,$E:$E,E4)/I4,0),0) -> 1 | L4: =K4*J4 -> 14.99 | M4: =G4/I4*J4 -> 1.7988
A5: Easy Chicken Pie | B5: Mains | C5: 1 rotisserie chicken (breast & thigh), sliced | D5: Costed | E5: rotisserie_chicken | F5: =INDEX('Woolworths Products'!$B$2:$B$208,MATCH($E5,'Woolworths Products'!$A$2:$A$208,0)) -> Medium Rotisserie Chicken | G5: 1 | H5: =INDEX('Woolworths Products'!$G$2:$G$208,MATCH($E5,'Woolworths Products'!$A$2:$A$208,0)) -> ea | I5: =INDEX('Woolworths Products'!$F$2:$F$208,MATCH($E5,'Woolworths Products'!$A$2:$A$208,0)) -> 1 | J5: =INDEX('Woolworths Products'!$E$2:$E$208,MATCH($E5,'Woolworths Products'!$A$2:$A$208,0)) -> 119.99 | K5: =IF(COUNTIFS($A$2:A5,A5,$E$2:E5,E5)=1,ROUNDUP(SUMIFS($G:$G,$A:$A,A5,$E:$E,E5)/I5,0),0) -> 1 | L5: =K5*J5 -> 119.99 | M5: =G5/I5*J5 -> 119.99
A6: Easy Chicken Pie | B6: Mains | C6: Puff pastry | D6: Costed | E6: puff_pastry | F6: =INDEX('Woolworths Products'!$B$2:$B$208,MATCH($E6,'Woolworths Products'!$A$2:$A$208,0)) -> Frozen Puff Pastry Roll 400 g | G6: 1 | H6: =INDEX('Woolworths Products'!$G$2:$G$208,MATCH($E6,'Woolworths Products'!$A$2:$A$208,0)) -> ea | I6: =INDEX('Woolworths Products'!$F$2:$F$208,MATCH($E6,'Woolworths Products'!$A$2:$A$208,0)) -> 1 | J6: =INDEX('Woolworths Products'!$E$2:$E$208,MATCH($E6,'Woolworths Products'!$A$2:$A$208,0)) -> 42.99 | K6: =IF(COUNTIFS($A$2:A6,A6,$E$2:E6,E6)=1,ROUNDUP(SUMIFS($G:$G,$A:$A,A6,$E:$E,E6)/I6,0),0) -> 1 | L6: =K6*J6 -> 42.99 | M6: =G6/I6*J6 -> 42.99 | N6: Amount not given - assumed 1 roll
A7: Easy Chicken Pie | B7: Mains | C7: 1 egg, for brushing | D7: Costed | E7: eggs | F7: =INDEX('Woolworths Products'!$B$2:$B$208,MATCH($E7,'Woolworths Products'!$A$2:$A$208,0)) -> Free Range Mixed Sizes Chilled Eggs 6 pk | G7: 1 | H7: =INDEX('Woolworths Products'!$G$2:$G$208,MATCH($E7,'Woolworths Products'!$A$2:$A$208,0)) -> ea | I7: =INDEX('Woolworths Products'!$F$2:$F$208,MATCH($E7,'Woolworths Products'!$A$2:$A$208,0)) -> 6 | J7: =INDEX('Woolworths Products'!$E$2:$E$208,MATCH($E7,'Woolworths Products'!$A$2:$A$208,0)) -> 29.99 | K7: =IF(COUNTIFS($A$2:A7,A7,$E$2:E7,E7)=1,ROUNDUP(SUMIFS($G:$G,$A:$A,A7,$E:$E,E7)/I7,0),0) -> 1 | L7: =K7*J7 -> 29.99 | M7: =G7/I7*J7 -> 4.9983333
A8: Easy Chicken Pie | B8: Mains | C8: Green salad, to serve | D8: Costed | E8: salad_leaves | F8: =INDEX('Woolworths Products'!$B$2:$B$208,MATCH($E8,'Woolworths Products'!$A$2:$A$208,0)) -> Mixed Leaf Salad 180 g | G8: 1 | H8: =INDEX('Woolworths Products'!$G$2:$G$208,MATCH($E8,'Woolworths Products'!$A$2:$A$208,0)) -> ea | I8: =INDEX('Woolworths Products'!$F$2:$F$208,MATCH($E8,'Woolworths Products'!$A$2:$A$208,0)) -> 1 | J8: =INDEX('Woolworths Products'!$E$2:$E$208,MATCH($E8,'Woolworths Products'!$A$2:$A$208,0)) -> 29.99 | K8: =IF(COUNTIFS($A$2:A8,A8,$E$2:E8,E8)=1,ROUNDUP(SUMIFS($G:$G,$A:$A,A8,$E:$E,E8)/I8,0),0) -> 1 | L8: =K8*J8 -> 29.99 | M8: =G8/I8*J8 -> 29.99 | N8: Amount not given - assumed 1 bag
A9: Bougie-Up Your Veg (toppings) | B9: Sides & salads | C9: Cooked vegetables of choice | D9: Costed | E9: baby_marrows | F9: =INDEX('Woolworths Products'!$B$2:$B$208,MATCH($E9,'Woolworths Products'!$A$2:$A$208,0)) -> Baby Marrows 350 g | G9: 350 | H9: =INDEX('Woolworths Products'!$G$2:$G$208,MATCH($E9,'Woolworths Products'!$A$2:$A$208,0)) -> g | I9: =INDEX('Woolworths Products'!$F$2:$F$208,MATCH($E9,'Woolworths Products'!$A$2:$A$208,0)) -> 350 | J9: =INDEX('Woolworths Products'!$E$2:$E$208,MATCH($E9,'Woolworths Products'!$A$2:$A$208,0)) -> 32.99 | K9: =IF(COUNTIFS($A$2:A9,A9,$E$2:E9,E9)=1,ROUNDUP(SUMIFS($G:$G,$A:$A,A9,$E:$E,E9)/I9,0),0) -> 1 | L9: =K9*J9 -> 32.99 | M9: =G9/I9*J9 -> 32.99 | N9: Amount not given - assumed 1 punnet baby marrows as the veg
A10: Bougie-Up Your Veg (toppings) | B10: Sides & salads | C10: Feta, crumbled | D10: Costed | E10: feta | F10: =INDEX('Woolworths Products'!$B$2:$B$208,MATCH($E10,'Woolworths Products'!$A$2:$A$208,0)) -> Plain South African Feta Cheese 100 g | G10: 50 | H10: =INDEX('Woolworths Products'!$G$2:$G$208,MATCH($E10,'Woolworths Products'!$A$2:$A$208,0)) -> g | I10: =INDEX('Woolworths Products'!$F$2:$F$208,MATCH($E10,'Woolworths Products'!$A$2:$A$208,0)) -> 100 | J10: =INDEX('Woolworths Products'!$E$2:$E$208,MATCH($E10,'Woolworths Products'!$A$2:$A$208,0)) -> 24.99 | K10: =IF(COUNTIFS($A$2:A10,A10,$E$2:E10,E10)=1,ROUNDUP(SUMIFS($G:$G,$A:$A,A10,$E:$E,E10)/I10,0),0) -> 1 | L10: =K10*J10 -> 24.99 | M10: =G10/I10*J10 -> 12.495 | N10: Amount not given - assumed 50 g
A11: Bougie-Up Your Veg (toppings) | B11: Sides & salads | C11: Pomegranate seeds | D11: Costed | E11: pomegranate | F11: =INDEX('Woolworths Products'!$B$2:$B$208,MATCH($E11,'Woolworths Products'!$A$2:$A$208,0)) -> Pomegranate Rubies 175 g | G11: 50 | H11: =INDEX('Woolworths Products'!$G$2:$G$208,MATCH($E11,'Woolworths Products'!$A$2:$A$208,0)) -> g | I11: =INDEX('Woolworths Products'!$F$2:$F$208,MATCH($E11,'Woolworths Products'!$A$2:$A$208,0)) -> 175 | J11: =INDEX('Woolworths Products'!$E$2:$E$208,MATCH($E11,'Woolworths Products'!$A$2:$A$208,0)) -> 54.99 | K11: =IF(COUNTIFS($A$2:A11,A11,$E$2:E11,E11)=1,ROUNDUP(SUMIFS($G:$G,$A:$A,A11,$E:$E,E11)/I11,0),0) -> 1 | L11: =K11*J11 -> 54.99 | M11: =G11/I11*J11 -> 15.711429 | N11: Amount not given - assumed 50 g
A12: Bougie-Up Your Veg (toppings) | B12: Sides & salads | C12: Lemon zest | D12: Costed | E12: lemons | F12: =INDEX('Woolworths Products'!$B$2:$B$208,MATCH($E12,'Woolworths Products'!$A$2:$A$208,0)) -> Lemons 3 pk | G12: 1 | H12: =INDEX('Woolworths Products'!$G$2:$G$208,MATCH($E12,'Woolworths Products'!$A$2:$A$208,0)) -> ea | I12: =INDEX('Woolworths Products'!$F$2:$F$208,MATCH($E12,'Woolworths Products'!$A$2:$A$208,0)) -> 3 | J12: =INDEX('Woolworths Products'!$E$2:$E$208,MATCH($E12,'Woolworths Products'!$A$2:$A$208,0)) -> 27.99 | K12: =IF(COUNTIFS($A$2:A12,A12,$E$2:E12,E12)=1,ROUNDUP(SUMIFS($G:$G,$A:$A,A12,$E:$E,E12)/I12,0),0) -> 1 | L12: =K12*J12 -> 27.99 | M12: =G12/I12*J12 -> 9.33
A13: Bougie-Up Your Veg (toppings) | B13: Sides & salads | C13: Balsamic glaze | D13: Costed | E13: balsamic_glaze | F13: =INDEX('Woolworths Products'!$B$2:$B$208,MATCH($E13,'Woolworths Products'!$A$2:$A$208,0)) -> Plain Crema - Balsamic Vinegar Reduction 150 ml | G13: 15 | H13: =INDEX('Woolworths Products'!$G$2:$G$208,MATCH($E13,'Woolworths Products'!$A$2:$A$208,0)) -> ml | I13: =INDEX('Woolworths Products'!$F$2:$F$208,MATCH($E13,'Woolworths Products'!$A$2:$A$208,0)) -> 150 | J13: =INDEX('Woolworths Products'!$E$2:$E$208,MATCH($E13,'Woolworths Products'!$A$2:$A$208,0)) -> 72.99 | K13: =IF(COUNTIFS($A$2:A13,A13,$E$2:E13,E13)=1,ROUNDUP(SUMIFS($G:$G,$A:$A,A13,$E:$E,E13)/I13,0),0) -> 1 | L13: =K13*J13 -> 72.99 | M13: =G13/I13*J13 -> 7.299 | N13: Amount not given - assumed 1 Tbsp
A14: Bougie-Up Your Veg (toppings) | B14: Sides & salads | C14: Rocket leaves | D14: Costed | E14: rocket | F14: =INDEX('Woolworths Products'!$B$2:$B$208,MATCH($E14,'Woolworths Products'!$A$2:$A$208,0)) -> Fresh Wild Rocket 30 g | G14: 1 | H14: =INDEX('Woolworths Products'!$G$2:$G$208,MATCH($E14,'Woolworths Products'!$A$2:$A$208,0)) -> ea | I14: =INDEX('Woolworths Products'!$F$2:$F$208,MATCH($E14,'Woolworths Products'!$A$2:$A$208,0)) -> 1 | J14: =INDEX('Woolworths Products'!$E$2:$E$208,MATCH($E14,'Woolworths Products'!$A$2:$A$208,0)) -> 15.99 | K14: =IF(COUNTIFS($A$2:A14,A14,$E$2:E14,E14)=1,ROUNDUP(SUMIFS($G:$G,$A:$A,A14,$E:$E,E14)/I14,0),0) -> 1 | L14: =K14*J14 -> 15.99 | M14: =G14/I14*J14 -> 15.99 | N14: Amount not given - assumed 1 bag
A15: Bougie-Up Your Veg (toppings) | B15: Sides & salads | C15: Good olive oil | D15: Costed | E15: olive_oil | F15: =INDEX('Woolworths Products'!$B$2:$B$208,MATCH($E15,'Woolworths Products'!$A$2:$A$208,0)) -> Prince Albert Extra Virgin Olive Oil 250 ml | G15: 15 | H15: =INDEX('Woolworths Products'!$G$2:$G$208,MATCH($E15,'Woolworths Products'!$A$2:$A$208,0)) -> ml | I15: =INDEX('Woolworths Products'!$F$2:$F$208,MATCH($E15,'Woolworths Products'!$A$2:$A$208,0)) -> 250 | J15: =INDEX('Woolworths Products'!$E$2:$E$208,MATCH($E15,'Woolworths Products'!$A$2:$A$208,0)) -> 109.99 | K15: =IF(COUNTIFS($A$2:A15,A15,$E$2:E15,E15)=1,ROUNDUP(SUMIFS($G:$G,$A:$A,A15,$E:$E,E15)/I15,0),0) -> 1 | L15: =K15*J15 -> 109.99 | M15: =G15/I15*J15 -> 6.5994 | N15: Amount not given - assumed 1 Tbsp
A16: Spinach & Feta Filo Tart | B16: Mains | C16: 2–3 sheets filo pastry (+1 extra for topping) | D16: Costed | E16: filo | F16: =INDEX('Woolworths Products'!$B$2:$B$208,MATCH($E16,'Woolworths Products'!$A$2:$A$208,0)) -> Frozen Phyllo Pastry 500 g | G16: 100 | H16: =INDEX('Woolworths Products'!$G$2:$G$208,MATCH($E16,'Woolworths Products'!$A$2:$A$208,0)) -> g | I16: =INDEX('Woolworths Products'!$F$2:$F$208,MATCH($E16,'Woolworths Products'!$A$2:$A$208,0)) -> 500 | J16: =INDEX('Woolworths Products'!$E$2:$E$208,MATCH($E16,'Woolworths Products'!$A$2:$A$208,0)) -> 67.99 | K16: =IF(COUNTIFS($A$2:A16,A16,$E$2:E16,E16)=1,ROUNDUP(SUMIFS($G:$G,$A:$A,A16,$E:$E,E16)/I16,0),0) -> 1 | L16: =K16*J16 -> 67.99 | M16: =G16/I16*J16 -> 13.598 | N16: 4 sheets taken as ~100 g
A17: Spinach & Feta Filo Tart | B17: Mains | C17: Olive oil spray | D17: Costed | E17: olive_oil_spray | F17: =INDEX('Woolworths Products'!$B$2:$B$208,MATCH($E17,'Woolworths Products'!$A$2:$A$208,0)) -> Extra Virgin Olive Oil Spray 250 ml | G17: 3 | H17: =INDEX('Woolworths Products'!$G$2:$G$208,MATCH($E17,'Woolworths Products'!$A$2:$A$208,0)) -> ml | I17: =INDEX('Woolworths Products'!$F$2:$F$208,MATCH($E17,'Woolworths Products'!$A$2:$A$208,0)) -> 250 | J17: =INDEX('Woolworths Products'!$E$2:$E$208,MATCH($E17,'Woolworths Products'!$A$2:$A$208,0)) -> 199.99 | K17: =IF(COUNTIFS($A$2:A17,A17,$E$2:E17,E17)=1,ROUNDUP(SUMIFS($G:$G,$A:$A,A17,$E:$E,E17)/I17,0),0) -> 1 | L17: =K17*J17 -> 199.99 | M17: =G17/I17*J17 -> 2.39988 | N17: Amount not given - assumed a few sprays
A18: Spinach & Feta Filo Tart | B18: Mains | C18: 500 g spinach | D18: Costed | E18: spinach | F18: =INDEX('Woolworths Products'!$B$2:$B$208,MATCH($E18,'Woolworths Products'!$A$2:$A$208,0)) -> Whole Spinach 350 g | G18: 500 | H18: =INDEX('Woolworths Products'!$G$2:$G$208,MATCH($E18,'Woolworths Products'!$A$2:$A$208,0)) -> g | I18: =INDEX('Woolworths Products'!$F$2:$F$208,MATCH($E18,'Woolworths Products'!$A$2:$A$208,0)) -> 350 | J18: =INDEX('Woolworths Products'!$E$2:$E$208,MATCH($E18,'Woolworths Products'!$A$2:$A$208,0)) -> 22.99 | K18: =IF(COUNTIFS($A$2:A18,A18,$E$2:E18,E18)=1,ROUNDUP(SUMIFS($G:$G,$A:$A,A18,$E:$E,E18)/I18,0),0) -> 2 | L18: =K18*J18 -> 45.98 | M18: =G18/I18*J18 -> 32.842857
A19: Spinach & Feta Filo Tart | B19: Mains | C19: 2 eggs | D19: Costed | E19: eggs | F19: =INDEX('Woolworths Products'!$B$2:$B$208,MATCH($E19,'Woolworths Products'!$A$2:$A$208,0)) -> Free Range Mixed Sizes Chilled Eggs 6 pk | G19: 2 | H19: =INDEX('Woolworths Products'!$G$2:$G$208,MATCH($E19,'Woolworths Products'!$A$2:$A$208,0)) -> ea | I19: =INDEX('Woolworths Products'!$F$2:$F$208,MATCH($E19,'Woolworths Products'!$A$2:$A$208,0)) -> 6 | J19: =INDEX('Woolworths Products'!$E$2:$E$208,MATCH($E19,'Woolworths Products'!$A$2:$A$208,0)) -> 29.99 | K19: =IF(COUNTIFS($A$2:A19,A19,$E$2:E19,E19)=1,ROUNDUP(SUMIFS($G:$G,$A:$A,A19,$E:$E,E19)/I19,0),0) -> 1 | L19: =K19*J19 -> 29.99 | M19: =G19/I19*J19 -> 9.9966667
A20: Spinach & Feta Filo Tart | B20: Mains | C20: 1 round feta, crumbled | D20: Costed | E20: feta | F20: =INDEX('Woolworths Products'!$B$2:$B$208,MATCH($E20,'Woolworths Products'!$A$2:$A$208,0)) -> Plain South African Feta Cheese 100 g | G20: 100 | H20: =INDEX('Woolworths Products'!$G$2:$G$208,MATCH($E20,'Woolworths Products'!$A$2:$A$208,0)) -> g | I20: =INDEX('Woolworths Products'!$F$2:$F$208,MATCH($E20,'Woolworths Products'!$A$2:$A$208,0)) -> 100 | J20: =INDEX('Woolworths Products'!$E$2:$E$208,MATCH($E20,'Woolworths Products'!$A$2:$A$208,0)) -> 24.99 | K20: =IF(COUNTIFS($A$2:A20,A20,$E$2:E20,E20)=1,ROUNDUP(SUMIFS($G:$G,$A:$A,A20,$E:$E,E20)/I20,0),0) -> 1 | L20: =K20*J20 -> 24.99 | M20: =G20/I20*J20 -> 24.99 | N20: 1 round taken as 100 g
A21: Spinach & Feta Filo Tart | B21: Mains | C21: 1 onion, diced | D21: Costed | E21: onions | F21: =INDEX('Woolworths Products'!$B$2:$B$208,MATCH($E21,'Woolworths Products'!$A$2:$A$208,0)) -> Brown Onions 1 kg | G21: 150 | H21: =INDEX('Woolworths Products'!$G$2:$G$208,MATCH($E21,'Woolworths Products'!$A$2:$A$208,0)) -> g | I21: =INDEX('Woolworths Products'!$F$2:$F$208,MATCH($E21,'Woolworths Products'!$A$2:$A$208,0)) -> 1000 | J21: =INDEX('Woolworths Products'!$E$2:$E$208,MATCH($E21,'Woolworths Products'!$A$2:$A$208,0)) -> 39.9 | K21: =IF(COUNTIFS($A$2:A21,A21,$E$2:E21,E21)=1,ROUNDUP(SUMIFS($G:$G,$A:$A,A21,$E:$E,E21)/I21,0),0) -> 1 | L21: =K21*J21 -> 39.9 | M21: =G21/I21*J21 -> 5.985 | N21: 1 onion taken as 150 g
A22: Spinach & Feta Filo Tart | B22: Mains | C22: Zest of 1 lemon | D22: Costed | E22: lemons | F22: =INDEX('Woolworths Products'!$B$2:$B$208,MATCH($E22,'Woolworths Products'!$A$2:$A$208,0)) -> Lemons 3 pk | G22: 1 | H22: =INDEX('Woolworths Products'!$G$2:$G$208,MATCH($E22,'Woolworths Products'!$A$2:$A$208,0)) -> ea | I22: =INDEX('Woolworths Products'!$F$2:$F$208,MATCH($E22,'Woolworths Products'!$A$2:$A$208,0)) -> 3 | J22: =INDEX('Woolworths Products'!$E$2:$E$208,MATCH($E22,'Woolworths Products'!$A$2:$A$208,0)) -> 27.99 | K22: =IF(COUNTIFS($A$2:A22,A22,$E$2:E22,E22)=1,ROUNDUP(SUMIFS($G:$G,$A:$A,A22,$E:$E,E22)/I22,0),0) -> 1 | L22: =K22*J22 -> 27.99 | M22: =G22/I22*J22 -> 9.33
A23: Spinach & Feta Filo Tart | B23: Mains | C23: Sesame seeds | D23: Costed | E23: sesame_seeds | F23: =INDEX('Woolworths Products'!$B$2:$B$208,MATCH($E23,'Woolworths Products'!$A$2:$A$208,0)) -> White Sesame Seeds 250 g | G23: 9 | H23: =INDEX('Woolworths Products'!$G$2:$G$208,MATCH($E23,'Woolworths Products'!$A$2:$A$208,0)) -> g | I23: =INDEX('Woolworths Products'!$F$2:$F$208,MATCH($E23,'Woolworths Products'!$A$2:$A$208,0)) -> 250 | J23: =INDEX('Woolworths Products'!$E$2:$E$208,MATCH($E23,'Woolworths Products'!$A$2:$A$208,0)) -> 64.99 | K23: =IF(COUNTIFS($A$2:A23,A23,$E$2:E23,E23)=1,ROUNDUP(SUMIFS($G:$G,$A:$A,A23,$E:$E,E23)/I23,0),0) -> 1 | L23: =K23*J23 -> 64.99 | M23: =G23/I23*J23 -> 2.33964 | N23: Amount not given - assumed 1 Tbsp
A24: Spinach & Feta Filo Tart | B24: Mains | C24: Salt | D24: Basic - not costed | L24: 0 | M24: 0 | N24: Salt
A25: Pampoen Tert (lower-sugar) | B25: Baking & sweet treats | C25: 800 g pumpkin, cooked & mashed | D25: Costed | E25: pumpkin | F25: =INDEX('Woolworths Products'!$B$2:$B$208,MATCH($E25,'Woolworths Products'!$A$2:$A$208,0)) -> Bulk Pumpkin 800 g | G25: 800 | H25: =INDEX('Woolworths Products'!$G$2:$G$208,MATCH($E25,'Woolworths Products'!$A$2:$A$208,0)) -> g | I25: =INDEX('Woolworths Products'!$F$2:$F$208,MATCH($E25,'Woolworths Products'!$A$2:$A$208,0)) -> 800 | J25: =INDEX('Woolworths Products'!$E$2:$E$208,MATCH($E25,'Woolworths Products'!$A$2:$A$208,0)) -> 49.99 | K25: =IF(COUNTIFS($A$2:A25,A25,$E$2:E25,E25)=1,ROUNDUP(SUMIFS($G:$G,$A:$A,A25,$E:$E,E25)/I25,0),0) -> 1 | L25: =K25*J25 -> 49.99 | M25: =G25/I25*J25 -> 49.99
A26: Pampoen Tert (lower-sugar) | B26: Baking & sweet treats | C26: 2 cups flour | D26: Costed | E26: cake_flour | F26: =INDEX('Woolworths Products'!$B$2:$B$208,MATCH($E26,'Woolworths Products'!$A$2:$A$208,0)) -> Cake Wheat Flour 1 kg | G26: 250 | H26: =INDEX('Woolworths Products'!$G$2:$G$208,MATCH($E26,'Woolworths Products'!$A$2:$A$208,0)) -> g | I26: =INDEX('Woolworths Products'!$F$2:$F$208,MATCH($E26,'Woolworths Products'!$A$2:$A$208,0)) -> 1000 | J26: =INDEX('Woolworths Products'!$E$2:$E$208,MATCH($E26,'Woolworths Products'!$A$2:$A$208,0)) -> 21.99 | K26: =IF(COUNTIFS($A$2:A26,A26,$E$2:E26,E26)=1,ROUNDUP(SUMIFS($G:$G,$A:$A,A26,$E:$E,E26)/I26,0),0) -> 1 | L26: =K26*J26 -> 21.99 | M26: =G26/I26*J26 -> 5.4975 | N26: 1 cup flour = 125 g
A27: Pampoen Tert (lower-sugar) | B27: Baking & sweet treats | C27: 3 eggs | D27: Costed | E27: eggs | F27: =INDEX('Woolworths Products'!$B$2:$B$208,MATCH($E27,'Woolworths Products'!$A$2:$A$208,0)) -> Free Range Mixed Sizes Chilled Eggs 6 pk | G27: 3 | H27: =INDEX('Woolworths Products'!$G$2:$G$208,MATCH($E27,'Woolworths Products'!$A$2:$A$208,0)) -> ea | I27: =INDEX('Woolworths Products'!$F$2:$F$208,MATCH($E27,'Woolworths Products'!$A$2:$A$208,0)) -> 6 | J27: =INDEX('Woolworths Products'!$E$2:$E$208,MATCH($E27,'Woolworths Products'!$A$2:$A$208,0)) -> 29.99 | K27: =IF(COUNTIFS($A$2:A27,A27,$E$2:E27,E27)=1,ROUNDUP(SUMIFS($G:$G,$A:$A,A27,$E:$E,E27)/I27,0),0) -> 1 | L27: =K27*J27 -> 29.99 | M27: =G27/I27*J27 -> 14.995
A28: Pampoen Tert (lower-sugar) | B28: Baking & sweet treats | C28: ¼ cup sugar | D28: Costed | E28: white_sugar | F28: =INDEX('Woolworths Products'!$B$2:$B$208,MATCH($E28,'Woolworths Products'!$A$2:$A$208,0)) -> White Sugar 1 kg | G28: 50 | H28: =INDEX('Woolworths Products'!$G$2:$G$208,MATCH($E28,'Woolworths Products'!$A$2:$A$208,0)) -> g | I28: =INDEX('Woolworths Products'!$F$2:$F$208,MATCH($E28,'Woolworths Products'!$A$2:$A$208,0)) -> 1000 | J28: =INDEX('Woolworths Products'!$E$2:$E$208,MATCH($E28,'Woolworths Products'!$A$2:$A$208,0)) -> 33.99 | K28: =IF(COUNTIFS($A$2:A28,A28,$E$2:E28,E28)=1,ROUNDUP(SUMIFS($G:$G,$A:$A,A28,$E:$E,E28)/I28,0),0) -> 1 | L28: =K28*J28 -> 33.99 | M28: =G28/I28*J28 -> 1.6995
A29: Pampoen Tert (lower-sugar) | B29: Baking & sweet treats | C29: 3 tsp baking powder | D29: Costed | E29: baking_powder | F29: =INDEX('Woolworths Products'!$B$2:$B$208,MATCH($E29,'Woolworths Products'!$A$2:$A$208,0)) -> Baking Powder 100 g | G29: 12 | H29: =INDEX('Woolworths Products'!$G$2:$G$208,MATCH($E29,'Woolworths Products'!$A$2:$A$208,0)) -> g | I29: =INDEX('Woolworths Products'!$F$2:$F$208,MATCH($E29,'Woolworths Products'!$A$2:$A$208,0)) -> 100 | J29: =INDEX('Woolworths Products'!$E$2:$E$208,MATCH($E29,'Woolworths Products'!$A$2:$A$208,0)) -> 34.99 | K29: =IF(COUNTIFS($A$2:A29,A29,$E$2:E29,E29)=1,ROUNDUP(SUMIFS($G:$G,$A:$A,A29,$E:$E,E29)/I29,0),0) -> 1 | L29: =K29*J29 -> 34.99 | M29: =G29/I29*J29 -> 4.1988 | N29: 1 tsp = 4 g
A30: Pampoen Tert (lower-sugar) | B30: Baking & sweet treats | C30: 1 tsp salt | D30: Basic - not costed | L30: 0 | M30: 0 | N30: Salt
A31: Pampoen Tert (lower-sugar) | B31: Baking & sweet treats | C31: 1 Tbsp vanilla essence | D31: Costed | E31: vanilla_essence | F31: =INDEX('Woolworths Products'!$B$2:$B$208,MATCH($E31,'Woolworths Products'!$A$2:$A$208,0)) -> Vanilla Essence 50 ml | G31: 15 | H31: =INDEX('Woolworths Products'!$G$2:$G$208,MATCH($E31,'Woolworths Products'!$A$2:$A$208,0)) -> ml | I31: =INDEX('Woolworths Products'!$F$2:$F$208,MATCH($E31,'Woolworths Products'!$A$2:$A$208,0)) -> 50 | J31: =INDEX('Woolworths Products'!$E$2:$E$208,MATCH($E31,'Woolworths Products'!$A$2:$A$208,0)) -> 29.99 | K31: =IF(COUNTIFS($A$2:A31,A31,$E$2:E31,E31)=1,ROUNDUP(SUMIFS($G:$G,$A:$A,A31,$E:$E,E31)/I31,0),0) -> 1 | L31: =K31*J31 -> 29.99 | M31: =G31/I31*J31 -> 8.997
A32: Pampoen Tert (lower-sugar) | B32: Baking & sweet treats | C32: 50 g butter, melted | D32: Costed | E32: butter | F32: =INDEX('Woolworths Products'!$B$2:$B$208,MATCH($E32,'Woolworths Products'!$A$2:$A$208,0)) -> Salted Butter 250 g | G32: 50 | H32: =INDEX('Woolworths Products'!$G$2:$G$208,MATCH($E32,'Woolworths Products'!$A$2:$A$208,0)) -> g | I32: =INDEX('Woolworths Products'!$F$2:$F$208,MATCH($E32,'Woolworths Products'!$A$2:$A$208,0)) -> 250 | J32: =INDEX('Woolworths Products'!$E$2:$E$208,MATCH($E32,'Woolworths Products'!$A$2:$A$208,0)) -> 68.99 | K32: =IF(COUNTIFS($A$2:A32,A32,$E$2:E32,E32)=1,ROUNDUP(SUMIFS($G:$G,$A:$A,A32,$E:$E,E32)/I32,0),0) -> 1 | L32: =K32*J32 -> 68.99 | M32: =G32/I32*J32 -> 13.798
A33: Pampoen Tert (lower-sugar) | B33: Baking & sweet treats | C33: Cinnamon & sugar, to sprinkle | D33: Costed | E33: cinnamon | F33: =INDEX('Woolworths Products'!$B$2:$B$208,MATCH($E33,'Woolworths Products'!$A$2:$A$208,0)) -> Finely Ground Cinnamon Refill 30 g | G33: 3 | H33: =INDEX('Woolworths Products'!$G$2:$G$208,MATCH($E33,'Woolworths Products'!$A$2:$A$208,0)) -> g | I33: =INDEX('Woolworths Products'!$F$2:$F$208,MATCH($E33,'Woolworths Products'!$A$2:$A$208,0)) -> 30 | J33: =INDEX('Woolworths Products'!$E$2:$E$208,MATCH($E33,'Woolworths Products'!$A$2:$A$208,0)) -> 29.99 | K33: =IF(COUNTIFS($A$2:A33,A33,$E$2:E33,E33)=1,ROUNDUP(SUMIFS($G:$G,$A:$A,A33,$E:$E,E33)/I33,0),0) -> 1 | L33: =K33*J33 -> 29.99 | M33: =G33/I33*J33 -> 2.999 | N33: Amount not given - assumed 1 tsp cinnamon + 1 Tbsp sugar
A34: Pampoen Tert (lower-sugar) | B34: Baking & sweet treats | C34: Cinnamon & sugar, to sprinkle (part 2) | D34: Costed | E34: white_sugar | F34: =INDEX('Woolworths Products'!$B$2:$B$208,MATCH($E34,'Woolworths Products'!$A$2:$A$208,0)) -> White Sugar 1 kg | G34: 12 | H34: =INDEX('Woolworths Products'!$G$2:$G$208,MATCH($E34,'Woolworths Products'!$A$2:$A$208,0)) -> g | I34: =INDEX('Woolworths Products'!$F$2:$F$208,MATCH($E34,'Woolworths Products'!$A$2:$A$208,0)) -> 1000 | J34: =INDEX('Woolworths Products'!$E$2:$E$208,MATCH($E34,'Woolworths Products'!$A$2:$A$208,0)) -> 33.99 | K34: =IF(COUNTIFS($A$2:A34,A34,$E$2:E34,E34)=1,ROUNDUP(SUMIFS($G:$G,$A:$A,A34,$E:$E,E34)/I34,0),0) -> 0 | L34: =K34*J34 -> 0 | M34: =G34/I34*J34 -> 0.40788
A35: Sticky Glazed Meatloaf | B35: Mains | C35: 1 kg lean beef mince | D35: Costed | E35: lean_mince | F35: =INDEX('Woolworths Products'!$B$2:$B$208,MATCH($E35,'Woolworths Products'!$A$2:$A$208,0)) -> Halaal Lean Beef Mince 500 g | G35: 1000 | H35: =INDEX('Woolworths Products'!$G$2:$G$208,MATCH($E35,'Woolworths Products'!$A$2:$A$208,0)) -> g | I35: =INDEX('Woolworths Products'!$F$2:$F$208,MATCH($E35,'Woolworths Products'!$A$2:$A$208,0)) -> 500 | J35: =INDEX('Woolworths Products'!$E$2:$E$208,MATCH($E35,'Woolworths Products'!$A$2:$A$208,0)) -> 64.99 | K35: =IF(COUNTIFS($A$2:A35,A35,$E$2:E35,E35)=1,ROUNDUP(SUMIFS($G:$G,$A:$A,A35,$E:$E,E35)/I35,0),0) -> 2 | L35: =K35*J35 -> 129.98 | M35: =G35/I35*J35 -> 129.98
A36: Sticky Glazed Meatloaf | B36: Mains | C36: 1 medium onion, finely chopped | D36: Costed | E36: onions | F36: =INDEX('Woolworths Products'!$B$2:$B$208,MATCH($E36,'Woolworths Products'!$A$2:$A$208,0)) -> Brown Onions 1 kg | G36: 150 | H36: =INDEX('Woolworths Products'!$G$2:$G$208,MATCH($E36,'Woolworths Products'!$A$2:$A$208,0)) -> g | I36: =INDEX('Woolworths Products'!$F$2:$F$208,MATCH($E36,'Woolworths Products'!$A$2:$A$208,0)) -> 1000 | J36: =INDEX('Woolworths Products'!$E$2:$E$208,MATCH($E36,'Woolworths Products'!$A$2:$A$208,0)) -> 39.9 | K36: =IF(COUNTIFS($A$2:A36,A36,$E$2:E36,E36)=1,ROUNDUP(SUMIFS($G:$G,$A:$A,A36,$E:$E,E36)/I36,0),0) -> 1 | L36: =K36*J36 -> 39.9 | M36: =G36/I36*J36 -> 5.985 | N36: 1 onion taken as 150 g
A37: Sticky Glazed Meatloaf | B37: Mains | C37: 2 green apples, grated | D37: Costed | E37: green_apples | F37: =INDEX('Woolworths Products'!$B$2:$B$208,MATCH($E37,'Woolworths Products'!$A$2:$A$208,0)) -> Granny Smith Apples 4 pk | G37: 2 | H37: =INDEX('Woolworths Products'!$G$2:$G$208,MATCH($E37,'Woolworths Products'!$A$2:$A$208,0)) -> ea | I37: =INDEX('Woolworths Products'!$F$2:$F$208,MATCH($E37,'Woolworths Products'!$A$2:$A$208,0)) -> 4 | J37: =INDEX('Woolworths Products'!$E$2:$E$208,MATCH($E37,'Woolworths Products'!$A$2:$A$208,0)) -> 28.99 | K37: =IF(COUNTIFS($A$2:A37,A37,$E$2:E37,E37)=1,ROUNDUP(SUMIFS($G:$G,$A:$A,A37,$E:$E,E37)/I37,0),0) -> 1 | L37: =K37*J37 -> 28.99 | M37: =G37/I37*J37 -> 14.495
A38: Sticky Glazed Meatloaf | B38: Mains | C38: 2 large eggs | D38: Costed | E38: eggs | F38: =INDEX('Woolworths Products'!$B$2:$B$208,MATCH($E38,'Woolworths Products'!$A$2:$A$208,0)) -> Free Range Mixed Sizes Chilled Eggs 6 pk | G38: 2 | H38: =INDEX('Woolworths Products'!$G$2:$G$208,MATCH($E38,'Woolworths Products'!$A$2:$A$208,0)) -> ea | I38: =INDEX('Woolworths Products'!$F$2:$F$208,MATCH($E38,'Woolworths Products'!$A$2:$A$208,0)) -> 6 | J38: =INDEX('Woolworths Products'!$E$2:$E$208,MATCH($E38,'Woolworths Products'!$A$2:$A$208,0)) -> 29.99 | K38: =IF(COUNTIFS($A$2:A38,A38,$E$2:E38,E38)=1,ROUNDUP(SUMIFS($G:$G,$A:$A,A38,$E:$E,E38)/I38,0),0) -> 1 | L38: =K38*J38 -> 29.99 | M38: =G38/I38*J38 -> 9.9966667
A39: Sticky Glazed Meatloaf | B39: Mains | C39: 3 garlic cloves, minced | D39: Costed | E39: garlic | F39: =INDEX('Woolworths Products'!$B$2:$B$208,MATCH($E39,'Woolworths Products'!$A$2:$A$208,0)) -> Fresh Peeled Garlic 50 g | G39: 3 | H39: =INDEX('Woolworths Products'!$G$2:$G$208,MATCH($E39,'Woolworths Products'!$A$2:$A$208,0)) -> clove | I39: =INDEX('Woolworths Products'!$F$2:$F$208,MATCH($E39,'Woolworths Products'!$A$2:$A$208,0)) -> 10 | J39: =INDEX('Woolworths Products'!$E$2:$E$208,MATCH($E39,'Woolworths Products'!$A$2:$A$208,0)) -> 29.99 | K39: =IF(COUNTIFS($A$2:A39,A39,$E$2:E39,E39)=1,ROUNDUP(SUMIFS($G:$G,$A:$A,A39,$E:$E,E39)/I39,0),0) -> 1 | L39: =K39*J39 -> 29.99 | M39: =G39/I39*J39 -> 8.997 | N39: ~10 cloves per 50 g
A40: Sticky Glazed Meatloaf | B40: Mains | C40: 2 Tbsp tomato sauce | D40: Costed | E40: tomato_sauce | F40: =INDEX('Woolworths Products'!$B$2:$B$208,MATCH($E40,'Woolworths Products'!$A$2:$A$208,0)) -> All Gold Original Tomato Sauce 500 ml | G40: 30 | H40: =INDEX('Woolworths Products'!$G$2:$G$208,MATCH($E40,'Woolworths Products'!$A$2:$A$208,0)) -> ml | I40: =INDEX('Woolworths Products'!$F$2:$F$208,MATCH($E40,'Woolworths Products'!$A$2:$A$208,0)) -> 500 | J40: =INDEX('Woolworths Products'!$E$2:$E$208,MATCH($E40,'Woolworths Products'!$A$2:$A$208,0)) -> 37.99 | K40: =IF(COUNTIFS($A$2:A40,A40,$E$2:E40,E40)=1,ROUNDUP(SUMIFS($G:$G,$A:$A,A40,$E:$E,E40)/I40,0),0) -> 1 | L40: =K40*J40 -> 37.99 | M40: =G40/I40*J40 -> 2.2794
...

Sheet Woolworths Products
A1: Key | B1: Woolworths product | C1: Today's price (R) | D1: Regular price (R) | E1: Price used (R) | F1: Pack size | G1: Unit | H1: Price per unit (R) | I1: On promotion? | J1: Note | K1: Link
A2: choc_chips | B2: 27 % Cocoa Milk Chocolate Drops 200 g | C2: 119.99 | D2: 119.99 | E2: =IF('Notes & Assumptions'!$C$4="Regular",D2,C2) -> 119.99 | F2: 200 | G2: g | H2: =E2/F2 -> 0.59995 | I2: =IF(C2<D2,"Yes","") | K2: Open
A3: tomato_sauce | B3: All Gold Original Tomato Sauce 500 ml | C3: 37.99 | D3: 37.99 | E3: =IF('Notes & Assumptions'!$C$4="Regular",D3,C3) -> 37.99 | F3: 500 | G3: ml | H3: =E3/F3 -> 0.07598 | I3: =IF(C3<D3,"Yes","") | K3: Open
A4: artichokes | B4: Artichokes 350 g | C4: 59.99 | D4: 59.99 | E4: =IF('Notes & Assumptions'!$C$4="Regular",D4,C4) -> 59.99 | F4: 1 | G4: ea | H4: =E4/F4 -> 59.99 | I4: =IF(C4<D4,"Yes","") | J4: Closest match; check it is the tinned/brined type | K4: Open
A5: hoisin | B5: Asian Hoisin Sauce 150 ml | C5: 51.99 | D5: 51.99 | E5: =IF('Notes & Assumptions'!$C$4="Regular",D5,C5) -> 51.99 | F5: 150 | G5: ml | H5: =E5/F5 -> 0.3466 | I5: =IF(C5<D5,"Yes","") | K5: Open
A6: egg_noodles | B6: Asian Medium Wholewheat Noodles 340 g | C6: 59.99 | D6: 59.99 | E6: =IF('Notes & Assumptions'!$C$4="Regular",D6,C6) -> 59.99 | F6: 6 | G6: nest | H6: =E6/F6 -> 9.9983333 | I6: =IF(C6<D6,"Yes","") | J6: ~6 nests per 340 g | K6: Open
A7: rice_vinegar | B7: Asian Rice Vinegar 200 ml | C7: 82.99 | D7: 82.99 | E7: =IF('Notes & Assumptions'!$C$4="Regular",D7,C7) -> 82.99 | F7: 200 | G7: ml | H7: =E7/F7 -> 0.41495 | I7: =IF(C7<D7,"Yes","") | K7: Open
A8: pickled_ginger | B8: Asian Sliced Ginger 120 g | C8: 64.99 | D8: 64.99 | E8: =IF('Notes & Assumptions'!$C$4="Regular",D8,C8) -> 64.99 | F8: 120 | G8: g | H8: =E8/F8 -> 0.54158333 | I8: =IF(C8<D8,"Yes","") | K8: Open
A9: avocado_oil | B9: Avocado Oil 250 ml | C9: 86.99 | D9: 86.99 | E9: =IF('Notes & Assumptions'!$C$4="Regular",D9,C9) -> 86.99 | F9: 250 | G9: ml | H9: =E9/F9 -> 0.34796 | I9: =IF(C9<D9,"Yes","") | K9: Open
A10: buttermilk | B10: Ayrshire Cultured Low Fat Buttermilk 500 ml | C10: 18.99 | D10: 18.99 | E10: =IF('Notes & Assumptions'!$C$4="Regular",D10,C10) -> 18.99 | F10: 500 | G10: ml | H10: =E10/F10 -> 0.03798 | I10: =IF(C10<D10,"Yes","") | K10: Open
A11: plain_yoghurt | B11: Ayrshire Full Cream Plain Yoghurt 500 g | C11: 39.99 | D11: 39.99 | E11: =IF('Notes & Assumptions'!$C$4="Regular",D11,C11) -> 39.99 | F11: 500 | G11: g | H11: =E11/F11 -> 0.07998 | I11: =IF(C11<D11,"Yes","") | K11: Open
A12: baby_marrows | B12: Baby Marrows 350 g | C12: 32.99 | D12: 32.99 | E12: =IF('Notes & Assumptions'!$C$4="Regular",D12,C12) -> 32.99 | F12: 350 | G12: g | H12: =E12/F12 -> 0.094257143 | I12: =IF(C12<D12,"Yes","") | K12: Open
A13: baby_spinach | B13: Baby Spinach 200 g | C13: 35.99 | D13: 35.99 | E13: =IF('Notes & Assumptions'!$C$4="Regular",D13,C13) -> 35.99 | F13: 200 | G13: g | H13: =E13/F13 -> 0.17995 | I13: =IF(C13<D13,"Yes","") | K13: Open
A14: cream_crackers | B14: Bakers Cream Crackers 200 g | C14: 32.99 | D14: 32.99 | E14: =IF('Notes & Assumptions'!$C$4="Regular",D14,C14) -> 32.99 | F14: 24 | G14: ea | H14: =E14/F14 -> 1.3745833 | I14: =IF(C14<D14,"Yes","") | J14: ~24 crackers per 200 g | K14: Open
A15: baking_powder | B15: Baking Powder 100 g | C15: 34.99 | D15: 34.99 | E15: =IF('Notes & Assumptions'!$C$4="Regular",D15,C15) -> 34.99 | F15: 100 | G15: g | H15: =E15/F15 -> 0.3499 | I15: =IF(C15<D15,"Yes","") | K15: Open
A16: pesto | B16: Basil Pesto 140 g | C16: 69.99 | D16: 69.99 | E16: =IF('Notes & Assumptions'!$C$4="Regular",D16,C16) -> 69.99 | F16: 140 | G16: g | H16: =E16/F16 -> 0.49992857 | I16: =IF(C16<D16,"Yes","") | K16: Open
A17: beef_shin | B17: Beef Shin Avg 600 g | C17: 107.99 | D17: 107.99 | E17: =IF('Notes & Assumptions'!$C$4="Regular",D17,C17) -> 107.99 | F17: 600 | G17: g | H17: =E17/F17 -> 0.17998333 | I17: =IF(C17<D17,"Yes","") | J17: Priced by weight; 1 shin taken as 300 g | K17: Open
A18: beef_stock_powder | B18: Beef Stock Powder 150 g | C18: 60.99 | D18: 60.99 | E18: =IF('Notes & Assumptions'!$C$4="Regular",D18,C18) -> 60.99 | F18: 150 | G18: g | H18: =E18/F18 -> 0.4066 | I18: =IF(C18<D18,"Yes","") | J18: No stock cubes listed; 1 cube taken as 10 g powder | K18: Open
A19: beetroot | B19: Beetroot Min 500 g | C19: 26.99 | D19: 26.99 | E19: =IF('Notes & Assumptions'!$C$4="Regular",D19,C19) -> 26.99 | F19: 500 | G19: g | H19: =E19/F19 -> 0.05398 | I19: =IF(C19<D19,"Yes","") | K19: Open
A20: bicarb | B20: Bicarbonate Of Soda 200 g | C20: 33.99 | D20: 33.99 | E20: =IF('Notes & Assumptions'!$C$4="Regular",D20,C20) -> 33.99 | F20: 200 | G20: g | H20: =E20/F20 -> 0.16995 | I20: =IF(C20<D20,"Yes","") | K20: Open
A21: bovril | B21: Bovril Meat And Vegetable Extract Spread 125 g | C21: 42.99 | D21: 42.99 | E21: =IF('Notes & Assumptions'!$C$4="Regular",D21,C21) -> 42.99 | F21: 125 | G21: g | H21: =E21/F21 -> 0.34392 | I21: =IF(C21<D21,"Yes","") | K21: Open
A22: mixed_seeds | B22: Breakfast Seed Mix 250 g | C22: 59.99 | D22: 59.99 | E22: =IF('Notes & Assumptions'!$C$4="Regular",D22,C22) -> 59.99 | F22: 250 | G22: g | H22: =E22/F22 -> 0.23996 | I22: =IF(C22<D22,"Yes","") | K22: Open
A23: brinjals | B23: Brinjals 1 kg | C23: 51.99 | D23: 51.99 | E23: =IF('Notes & Assumptions'!$C$4="Regular",D23,C23) -> 51.99 | F23: 1000 | G23: g | H23: =E23/F23 -> 0.05199 | I23: =IF(C23<D23,"Yes","") | K23: Open
A24: brown_onion_thickener | B24: Brown Onion Flavoured Thickener 40 g | C24: 23.99 | D24: 23.99 | E24: =IF('Notes & Assumptions'!$C$4="Regular",D24,C24) -> 23.99 | F24: 1 | G24: ea | H24: =E24/F24 -> 23.99 | I24: =IF(C24<D24,"Yes","") | J24: SUBSTITUTE: Knorr brown onion soup not sold | K24: Open
A25: onions | B25: Brown Onions 1 kg | C25: 39.9 | D25: 39.9 | E25: =IF('Notes & Assumptions'!$C$4="Regular",D25,C25) -> 39.9 | F25: 1000 | G25: g | H25: =E25/F25 -> 0.0399 | I25: =IF(C25<D25,"Yes","") | J25: 1 onion taken as 150 g | K25: Open
A26: brussels | B26: Brussels Sprouts 300 g | C26: 49.99 | D26: 49.99 | E26: =IF('Notes & Assumptions'!$C$4="Regular",D26,C26) -> 49.99 | F26: 1 | G26: ea | H26: =E26/F26 -> 49.99 | I26: =IF(C26<D26,"Yes","") | K26: Open
A27: bulgur | B27: Bulgur Wheat 500 g | C27: 44.99 | D27: 44.99 | E27: =IF('Notes & Assumptions'!$C$4="Regular",D27,C27) -> 44.99 | F27: 500 | G27: g | H27: =E27/F27 -> 0.08998 | I27: =IF(C27<D27,"Yes","") | K27: Open
A28: pumpkin | B28: Bulk Pumpkin 800 g | C28: 49.99 | D28: 49.99 | E28: =IF('Notes & Assumptions'!$C$4="Regular",D28,C28) -> 49.99 | F28: 800 | G28: g | H28: =E28/F28 -> 0.0624875 | I28: =IF(C28<D28,"Yes","") | K28: Open
A29: slaw | B29: Burger Slaw 250 g | C29: 24.99 | D29: 24.99 | E29: =IF('Notes & Assumptions'!$C$4="Regular",D29,C29) -> 24.99 | F29: 1 | G29: ea | H29: =E29/F29 -> 24.99 | I29: =IF(C29<D29,"Yes","") | K29: Open
A30: butter_chicken_sauce | B30: Butter Chicken Cook-in-Sauce 400 g | C30: 60.99 | D30: 69.99 | E30: =IF('Notes & Assumptions'!$C$4="Regular",D30,C30) -> 60.99 | F30: 1 | G30: ea | H30: =E30/F30 -> 60.99 | I30: =IF(C30<D30,"Yes","") -> Yes | J30: SUBSTITUTE: Woolworths Butter Chicken Soup not currently listed | K30: Open
A31: butternut | B31: Butternut Avg 900 g | C31: 24.93 | D31: 24.93 | E31: =IF('Notes & Assumptions'!$C$4="Regular",D31,C31) -> 24.93 | F31: 1 | G31: ea | H31: =E31/F31 -> 24.93 | I31: =IF(C31<D31,"Yes","") | J31: Priced by weight | K31: Open
A32: milk_choc | B32: Cadbury Dairy Milk Chocolate Bar 80 g | C32: 25.99 | D32: 25.99 | E32: =IF('Notes & Assumptions'!$C$4="Regular",D32,C32) -> 25.99 | F32: 80 | G32: g | H32: =E32/F32 -> 0.324875 | I32: =IF(C32<D32,"Yes","") | K32: Open
A33: cadbury | B33: Cadbury Dairy Milk Chocolate Slab 150 g | C33: 49.99 | D33: 49.99 | E33: =IF('Notes & Assumptions'!$C$4="Regular",D33,C33) -> 49.99 | F33: 150 | G33: g | H33: =E33/F33 -> 0.33326667 | I33: =IF(C33<D33,"Yes","") | J33: Woolworths sells 150 g slabs, not 180 g | K33: Open
A34: cake_flour | B34: Cake Wheat Flour 1 kg | C34: 21.99 | D34: 21.99 | E34: =IF('Notes & Assumptions'!$C$4="Regular",D34,C34) -> 21.99 | F34: 1000 | G34: g | H34: =E34/F34 -> 0.02199 | I34: =IF(C34<D34,"Yes","") | K34: Open
A35: canola_oil | B35: Canola Oil 750 ml | C35: 39.99 | D35: 39.99 | E35: =IF('Notes & Assumptions'!$C$4="Regular",D35,C35) -> 39.99 | F35: 750 | G35: ml | H35: =E35/F35 -> 0.05332 | I35: =IF(C35<D35,"Yes","") | K35: Open
A36: carrot_muffin | B36: Carrot & Pecan Nut Muffins 4 pk | C36: 54.99 | D36: 54.99 | E36: =IF('Notes & Assumptions'!$C$4="Regular",D36,C36) -> 54.99 | F36: 4 | G36: ea | H36: =E36/F36 -> 13.7475 | I36: =IF(C36<D36,"Yes","") | K36: Open
A37: celery | B37: Celery | C37: 28.99 | D37: 28.99 | E37: =IF('Notes & Assumptions'!$C$4="Regular",D37,C37) -> 28.99 | F37: 10 | G37: stick | H37: =E37/F37 -> 2.899 | I37: =IF(C37<D37,"Yes","") | J37: ~10 sticks per head | K37: Open
A38: goats_cheese | B38: Chevin Goat's Full Fat Cheese 100 g | C38: 62.99 | D38: 62.99 | E38: =IF('Notes & Assumptions'!$C$4="Regular",D38,C38) -> 62.99 | F38: 100 | G38: g | H38: =E38/F38 -> 0.6299 | I38: =IF(C38<D38,"Yes","") | K38: Open
A39: chia | B39: Chia Seeds 250 g | C39: 109.99 | D39: 109.99 | E39: =IF('Notes & Assumptions'!$C$4="Regular",D39,C39) -> 109.99 | F39: 250 | G39: g | H39: =E39/F39 -> 0.43996 | I39: =IF(C39<D39,"Yes","") | K39: Open
A40: chicken_sauce_powder | B40: Chicken A La King Cook In Sauce 37 g | C40: 19.99 | D40: 19.99 | E40: =IF('Notes & Assumptions'!$C$4="Regular",D40,C40) -> 19.99 | F40: 1 | G40: ea | H40: =E40/F40 -> 19.99 | I40: =IF(C40<D40,"Yes","") | J40: SUBSTITUTE: no cream of chicken soup powder at Woolworths | K40: Open
...

Sheet Notes & Assumptions
B2: Woolworths recipe costing
B4: Price basis (choose) | C4: Today
C5: "Today" uses the price shown on woolworths.co.za on 6 Oct 2026, including any promotion. "Regular" uses the pre-promotion price where an item was on promotion.
B7: Prices captured | C7: woolworths.co.za online prices, 6 October 2026 (Cape Town region). Prices change often and some items differ in store.
B8: Product choice | C8: Cheapest Woolworths item that matches the ingredient. Where the recipe names a specific pack (e.g. 600 g fresh soup, 400 g punnet) that pack is used.
B9: Two costs per recipe | C9: Cost per make = only the share of each pack the recipe uses. Shop-from-scratch = full packs you would have to buy (packs are rounded up per recipe).
B10: Left out | C10: Salt, pepper, water and "seasoning of choice" are not costed, as agreed.
B11: Not at Woolworths | C11: Psyllium husk (Bovril Seed Crackers) and tamarillos (Tree Tomato Chutney) are not sold, so those recipes are understated. Sambals with the curry are not costed.
B12: Substitutes | C12: Where Woolworths does not stock the named item a close match is used and flagged in yellow on the Ingredient Costing sheet (e.g. HP sauce, Knorr soups, Lancewood yoghurt, Woolworths butter chicken and Moroccan lamb soups, Dr. Oetker spinach & feta).
B13: Vague amounts | C13: Where the recipe gives no amount (e.g. "Feta, crumbled", "Fresh thyme") a sensible amount is assumed and written in the Note column. Change any blue Qty cell to update all totals.
B14: Conversions | C14: 1 cup = 250 ml; 1 Tbsp = 15 ml; 1 tsp = 5 ml. Flour 125 g/cup; sugar 200 g/cup; oats 90 g/cup; peas 140 g/cup; 1 onion 150 g; 1 potato 200 g; 1 carrot 80 g; 1 baby marrow 70 g; 1 feta round 100 g; 1 garlic clove from a 10-clove pack; fresh herbs costed as a share of a punnet.
B15: Priced by weight | C15: Meat, butternut, broccoli and cauliflower are sold by average weight, so the till price can differ slightly.
